<?xml version="1.0"?>
<robot name="four_wheel_car" xmlns:xacro="http://ros.org/wiki/xacro">

    <!-- Macro for SmartCar body. Including Gazebo extensions, but does not include Kinect -->
    <include filename="$(find four_wheel_car_description)/urdf/four_wheel_car.gazebo.urdf.xacro" />


    <xacro:macro name="four_wheel_car_body">

        <link name="base_link">
            <!-- <inertial>
            <origin xyz="0 1 0.5" rpy="0 0 0" />
            <mass value="1" />
            <inertia ixx="100" ixy="0" ixz="0" iyy="100" iyz="0" izz="100" />
        </inertial> -->

            <visual>
                <origin xyz="0 0 0.4" rpy="0 0 0" />
                <geometry>
                    <box size="1 0.9 0.4" />
                </geometry>
                <material name="yellow">
                    <color rgba="1 0.4 0 1" />
                </material>
            </visual>

            <collision>
                <origin xyz="0 0 0.4" rpy="0 0 0" />
                <geometry>
                    <box size="1 0.9 0.4" />
                </geometry>
            </collision>
        </link>


        <joint name="wheel_right_front_joint" type="continuous">
            <parent link="base_link" />
            <child link="wheel_right_front_link" />
            <origin xyz="0.25 -0.425 0.1" rpy="0 0 1.57" />
            <axis xyz="0 0 1" />
        </joint>

        <link name="wheel_right_front_link">

            <!-- <inertial>
            <origin xyz="0 0 0" />
            <mass value="2.8498940e-02" />
            <inertia ixx="1.1175580e-05" ixy="-4.2369783e-11" ixz="-5.9381719e-09" iyy="1.1192413e-05" iyz="-1.4400107e-11" izz="2.0712558e-05" />
        </inertial>  -->

            <visual>
                <origin xyz="0 0 0" rpy="0 1.57 0" />
                <geometry>
                    <cylinder length="0.05" radius="0.1" />
                </geometry>
                <material name="dark">
                    <color rgba="1 1 1 1" />
                </material>
            </visual>

            <collision>
                <origin xyz="0 0 0" rpy="0 1.57 0" />
                <geometry>
                    <cylinder length="0.05" radius="0.1" />
                </geometry>
            </collision>

        </link>


        <joint name="wheel_left_front_joint" type="continuous">
            <parent link="base_link" />
            <child link="wheel_left_front_link" />
            <origin xyz="0.25 0.425 0.1" rpy="0 0 1.57" />
            <axis xyz="0 0 1" />
        </joint>

        <link name="wheel_left_front_link">
            <visual>
                <origin xyz="0 0 0" rpy="0 1.57 0" />
                <geometry>
                    <cylinder length="0.05" radius="0.1" />
                </geometry>
                <material name="dark">
                    <color rgba="1 1 1 1" />
                </material>
            </visual>

            <collision>
                <origin xyz="0 0 0" rpy="0 1.57 0" />
                <geometry>
                    <cylinder length="0.05" radius="0.1" />
                </geometry>
            </collision>
        </link>

        <joint name="wheel_left_back_joint" type="continuous">
            <parent link="base_link" />
            <child link="wheel_left_back_link" />
            <origin xyz="-0.25 0.425 0.1" rpy="0 0 1.57" />
            <axis xyz="0 0 1" />
        </joint>

        <link name="wheel_left_back_link">
            <visual>
                <origin xyz="0 0 0" rpy="0 1.57 0" />
                <geometry>
                    <cylinder length="0.05" radius="0.1" />
                </geometry>
                <material name="dark">
                    <color rgba="1 1 1 1" />
                </material>
            </visual>
            <collision>
                <origin xyz="0 0 0" rpy="0 1.57 0" />
                <geometry>
                    <cylinder length="0.05" radius="0.1" />
                </geometry>
            </collision>
        </link>

        <joint name="wheel_right_back_joint" type="continuous">
            <parent link="base_link" />
            <child link="wheel_right_back_link" />
            <origin xyz="-0.25 -0.425 0.1" rpy="0 0 1.57" />
            <axis xyz="0 0 1" />
        </joint>

        <link name="wheel_right_back_link">
            <visual>
                <origin xyz="0 0 0" rpy="0 1.57 0" />
                <geometry>
                    <cylinder length="0.05" radius="0.1" />
                </geometry>
                <material name="dark">
                    <color rgba="1 1 1 1" />
                </material>
            </visual>

            <collision>
                <origin xyz="0 0 0" rpy="0 1.57 0" />
                <geometry>
                    <cylinder length="0.05" radius="0.1" />
                </geometry>
            </collision>
        </link>
    </xacro:macro>

</robot>